Workbook

Sheet Cover
B2: CREDIT ANALYSIS
B3: ADENTRA Inc. (TSX: ADEN)
B4: Specialty Architectural Building Products Distribution
B7: Analyst | C7: Yuvrraj Rajput
B8: Date | C8: 22 April, 2026
B9: Fiscal Years | C9: FY2022 - FY2025
B10: Currency | C10: USD (thousands)
B11: Data Source | C11: ADENTRA Financial Reporting
B14: CREDIT RECOMMENDATION
B15: Conditional Approval — Senior Secured Revolving Credit Facility subject to leverage and coverage covenants.
B19: MODEL CONTENTS
B20: Income Statement | C20: Revenue, EBITDA, Margins and Profitability
B21: Balance Sheet | C21: Assets, Liabilities and Shareholder's Equity
B22: Cash Flow | C22: Operating, Investing and Financing Cash Flows
B23: Credit Metrics | C23: Leverage, coverage, liquidity and efficiency ratios with trend analysis
B32: Confidential — Prepared for Portfolio and Educational Purposes Only.

Sheet Income Statement
A1: Income Statement (Expressed in thousands of US dollars)
A3: Line Item | B3: FY22 | C3: FY23 | D3: FY24 | E3: FY25
A4: Revenue | B4: 2579568 | C4: 2239324 | D4: 2184258 | E4: 2249266
A5: COGS | B5: -2022819 | C5: -1773222 | D5: -1710194 | E5: -1761415
A6: Gross Profit | B6: =B4+B5 -> 556749 | C6: =C4+C5 -> 466102 | D6: =D4+D5 -> 474064 | E6: =E4+E5 -> 487851
A7: Gross Margin % | B7: =B6/B4 -> 0.21583033 | C7: =C6/C4 -> 0.20814406 | D7: =D6/D4 -> 0.21703663 | E7: =E6/E4 -> 0.21689342
A9: Operating Expenses
A10: Selling, distribution and administration | B10: -338860 | C10: -310229 | D10: -308862 | E10: -308842
A11: Depreciation | C11: -40515 | D11: -42773 | E11: -47515
A12: Amortization of acquired intangible assets | B12: -21257 | C12: -23053 | D12: -25521 | E12: -28403
B13: =B10+B11+B12 -> -360117 | C13: =C10+C11+C12 -> -373797 | D13: =D10+D11+D12 -> -377156 | E13: =E10+E11+E12 -> -384760
A15: Income from operations | B15: =B6+B13 -> 196632 | C15: =C6+C13 -> 92305 | D15: =D6+D13 -> 96908 | E15: =E6+E13 -> 103091
A16: EBITDA | B16: =B15+B18 -> 262087 | C16: =C15+C18 -> 162162 | D16: =D15+D18 -> 173007 | E16: =E15+E18 -> 188113
A17: EBITDA % | B17: =B16/B4 -> 0.10160112 | C17: =C16/C4 -> 0.072415604 | D17: =D16/D4 -> 0.079206303 | E17: =E16/E4 -> 0.083633061
A18: Depreciation and Amortization | B18: 65455 | C18: 69857 | D18: 76099 | E18: 85022
A19: EBIT | B19: =B16-B18 -> 196632 | C19: =C16-C18 -> 92305 | D19: =D16-D18 -> 96908 | E19: =E16-E18 -> 103091
A21: Net Interest Expense | B21: -33862 | C21: -49406 | D21: -41614 | E21: -37048
A22: Pre-Tax Income | B22: =B19+B21 -> 162770 | C22: =C19+C21 -> 42899 | D22: =D19+D21 -> 55294 | E22: =E19+E21 -> 66043
A23: Income Tax | B23: -34102 | C23: -6851 | D23: -8816 | E23: 2385
A24: Net Income | B24: =B22+B23 -> 128668 | C24: =C22+C23 -> 36048 | D24: =D22+D23 -> 46478 | E24: =E22+E23 -> 68428
A25: Net Income Margin % | B25: =B24/B4 -> 0.04987967 | C25: =C24/C4 -> 0.016097715 | D25: =D24/D4 -> 0.021278622 | E25: =E24/E4 -> 0.030422369
A27: Revenue Growth YoY % | C27: =(C4-2579568)/2579568 -> -0.1318996 | D27: =(D4-C4)/C4 -> -0.024590457 | E27: =(E4-D4)/D4 -> 0.029762052

Sheet Balance Sheet
A1: Balance Sheet (Expressed in thousands of US dollars)
A3: Line Item | B3: FY22 | C3: FY23 | D3: FY24 | E3: FY25
A4: Current assets
A5: Cash and cash equivalents | B5: 65068 | C5: 3643 | D5: 28111 | E5: 1815
A6: Receivables and investments | B6: 188122 | C6: 189157 | D6: 184993 | E6: 181289
A7: Inventories | B7: 485758 | C7: 365777 | D7: 375718 | E7: 378543
A8: Income taxes receivable | B8: 3504 | C8: 8919 | D8: 3980 | E8: 5147
A9: Prepaid expenses | B9: 16754 | C9: 16556 | D9: 27840 | E9: 14080
A10: Total current assets | B10: =SUM(B5:B9) -> 759206 | C10: =SUM(C5:C9) -> 584052 | D10: =SUM(D5:D9) -> 620642 | E10: =SUM(E5:E9) -> 580874
A12: Non-Current Assets
A13: Receivables and investments | B13: 6870 | C13: 7980 | D13: 28309 | E13: 15138
A14: PP&E | B14: 36116 | C14: 38134 | D14: 41188 | E14: 45504
A15: Right of use assets | B15: 158861 | C15: 157095 | D15: 196101 | E15: 231298
A16: Intangible assets | B16: 282000 | C16: 260098 | D16: 305459 | E16: 277846
A17: Deferred income taxes | B17: 5671 | C17: 3632 | D17: 5456 | E17: 21825
A18: Goodwill | B18: 180250 | C18: 181128 | D18: 200496 | E18: 200496
A19: Total non-current assets | B19: =SUM(B13:B18) -> 669768 | C19: =SUM(C13:C18) -> 648067 | D19: =SUM(D13:D18) -> 777009 | E19: =SUM(E13:E18) -> 792107
A20: Total assets | B20: =B10+B19 -> 1428974 | C20: =C10+C19 -> 1232119 | D20: =D10+D19 -> 1397651 | E20: =E10+E19 -> 1372981
A22: Current liabilities
A23: Bank indebtedness | B23: 264368 | C23: 59050 | D23: 115347 | E23: 122250
A24: Accounts payable and accrued liability | B24: 129197 | C24: 131993 | D24: 121080 | E24: 107808
A25: Lease obligations | B25: 37690 | C25: 34309 | D25: 39305 | E25: 45347
A26: Dividend payable | B26: 2173 | C26: 2374 | D26: 2608 | E26: 2831
A27: Total current liabilities | B27: =SUM(B23:B26) -> 433428 | C27: =SUM(C23:C26) -> 227726 | D27: =SUM(D23:D26) -> 278340 | E27: =282890 -> 282890
A29: Non-current liabilities
A30: Bank indebtedness | B30: 351922 | C30: 333346 | D30: 295189 | E30: 198401
A31: Lease obligations | B31: 135877 | C31: 137324 | D31: 173225 | E31: 208935
A32: Other liabilities | B32: 775 | C32: 6856 | D32: 10023 | E32: 5768
A33: Total non-current liabilities | B33: =SUM(B30:B32) -> 488574 | C33: =SUM(C30:C32) -> 477526 | D33: 484739 | E33: 420070
A34: Total liabilities | B34: =B27+B33 -> 922002 | C34: =C27+C33 -> 705252 | D34: =D27+D33 -> 763079 | E34: =E27+E33 -> 702960
A36: Shareholder's equity | B36: 506972 | C36: 526867 | D36: 634572 | E36: 670021
A37: Total liabilities and shareholder's equity | B37: =B34+B36 -> 1428974 | C37: =C34+C36 -> 1232119 | D37: =D34+D36 -> 1397651 | E37: =E34+E36 -> 1372981

Sheet  Cash Flow
A1: Cash Flow Statement (Expressed in thousands of US dollars)
A3: Line Item | B3: FY22 | C3: FY23 | D3: FY24 | E3: FY25
A4: Cash flow from operating activities:
A5: Net income for the year | B5: 128668 | C5: 36048 | D5: 46478 | E5: 68428
A6: Adjustments for:
A7: Depreciation and amortization | B7: 65455 | C7: 69857 | D7: 76099 | E7: 85022
A8: Gain on sale of PP&E | B8: -396 | C8: -597 | D8: -430 | E8: 625
A9: Gain on deferred contingent consideration | E9: -1423
A10: Share-based compensation expense | B10: 3899 | C10: 7440 | D10: 9309 | E10: 9540
A11: Income tax (recovery) expense | B11: 34102 | C11: 6851 | D11: 8816 | E11: -2385
A12: Net finance expense | B12: 33862 | C12: 49406 | D12: 41614 | E12: 45732
A13: Interest Received | B13: 805 | C13: 625 | D13: 911 | E13: 3249
A14: Interest paid | B14: -30383 | C14: -42664 | D14: -34290 | E14: -36716
A15: Income taxes paid | B15: -53362 | C15: -8775 | D15: -724 | E15: -8619
B16: =SUM(B5:B15) -> 182650 | C16: =SUM(C5:C15) -> 118191 | D16: =SUM(D5:D15) -> 147783 | E16: =SUM(E5:E15) -> 163453
A17: Changes in non cash working capital:
A18: Accounts receivable | B18: 15576 | C18: -248 | D18: 16929 | E18: 9923
A19: Inventories | B19: 6125 | C19: 120823 | D19: 10927 | E19: -1565
A20: Prepaid expenses | B20: 15583 | C20: 237 | D20: -11373 | E20: 13821
A21: Accounts payable and accured liabilities | B21: -9249 | C21: -924 | D21: -21514 | E21: -24992
B22: =SUM(B18:B21) -> 28035 | C22: =SUM(C18:C21) -> 119888 | D22: =SUM(D18:D21) -> -5031 | E22: =SUM(E18:E21) -> -2813
A23: Net cash provided by operating activities | B23: =B16+B22 -> 210685 | C23: =C16+C22 -> 238079 | D23: =D16+D22 -> 142752 | E23: =E16+E22 -> 160640
A24: Free cash flow (FCF) | B24: =B23+(B38+B41) -> 199875 | C24: =C23+(C38+C41) -> 226298 | D24: =D23+(D38+D41) -> 133545 | E24: =E23+(E38+E41) -> 146379
A26: Cash flow from financing activites:
A27: Issuance of long-term bank indebtedness | B27: 100000
A28: Repayment of term loan | B28: -20000 | C28: -20000 | D28: -40000 | E28: -102501
A29: Proceeds from revolving credit loan | D29: 58223 | E29: 12629
A30: (Repayment) Issuance of short-term bank indebtedness | B30: 124730 | C30: -203595
A31: Principle payments on lease obligations | B31: -40138 | C31: -44596 | D31: -48050 | E31: -54339
A32: Equity offering, net of share issuance costs | D32: 69458
A33: Repurchase of common shares | B33: -27135 | C33: -9244 | E33: -18815
A34: Dividends paid to shareholders | B34: -8849 | C34: -8555 | D34: -9632 | E34: -10657
A35: Net cash (used in) provided by financing activities | B35: =SUM(B27:B34) -> 128608 | C35: =SUM(C28:C34) -> -285990 | D35: =SUM(D28:D34) -> 29999 | E35: =SUM(E28:E34) -> -173683
A37: Cash flow (used in) from investing activities:
A38: Additions to property, plant and equipment | B38: -7859 | C38: -10635 | D38: -8200 | E38: -13361
A39: Proceeds on disposal of property, plant and equipment | B39: 771 | C39: 700 | D39: 327 | E39: 322
A40: Business acquisitions | B40: -273651 | C40: -1300 | D40: -122250
A41: Additions to intangible assets | B41: -2951 | C41: -1146 | D41: -1007 | E41: -900
A42: (Increase) decrease in non-current receivables | B42: 327 | C42: -242 | D42: -15383 | E42: 14830
A43: (Increase) decrease in investments | B43: 3893 | C43: -858 | D43: -945 | E43: -7478
...

Sheet Credit Metrics
A1: Credit Metrics
A3: Line Item | B3: FY22 | C3: FY23 | D3: FY24 | E3: FY25
A4: Calculations
A5: Total debt | B5: ='Balance Sheet'!B23+'Balance Sheet'!B25+'Balance Sheet'!B30+'Balance Sheet'!B31 -> 789857 | C5: ='Balance Sheet'!C23+'Balance Sheet'!C25+'Balance Sheet'!C30+'Balance Sheet'!C31 -> 564029 | D5: ='Balance Sheet'!D23+'Balance Sheet'!D25+'Balance Sheet'!D30+'Balance Sheet'!D31 -> 623066 | E5: ='Balance Sheet'!E23+'Balance Sheet'!E25+'Balance Sheet'!E30+'Balance Sheet'!E31 -> 574933
A6: Net debt | B6: =B5-'Balance Sheet'!B5 -> 724789 | C6: =C5-'Balance Sheet'!C5 -> 560386 | D6: =D5-'Balance Sheet'!D5 -> 594955 | E6: =E5-'Balance Sheet'!E5 -> 573118
A7: Accounts receivable | B7: =14445+160556 -> 175001 | C7: =12651+152579 -> 165230 | D7: 159655 | E7: 151742
A8: Free cash flow (FCF) | B8: =' Cash Flow'!B24 -> 199875 | C8: =' Cash Flow'!C24 -> 226298 | D8: =' Cash Flow'!D24 -> 133545 | E8: =' Cash Flow'!E24 -> 146379
A9: FCF to total debt | B9: =B8/B5 -> 0.25305213 | C9: =C8/C5 -> 0.40121696 | D9: =D8/D5 -> 0.21433524 | E9: =E8/E5 -> 0.25460184
A11: Leverage ratios
A12: Total debt to EBITDA | B12: =(B5)/'Income Statement'!B16 -> 3.0137206 | C12: =(C5)/'Income Statement'!C16 -> 3.4781823 | D12: =(D5)/'Income Statement'!D16 -> 3.6013919 | E12: =(E5)/'Income Statement'!E16 -> 3.0563172
A13: Net debt to EBITDA | B13: =B6/'Income Statement'!B16 -> 2.7654519 | C13: =C6/'Income Statement'!C16 -> 3.4557171 | D13: =D6/'Income Statement'!D16 -> 3.4389071 | E13: =E6/'Income Statement'!E16 -> 3.0466688
A15: Coverage ratios
A16: Interest coverage ratio | B16: =-'Income Statement'!B19/' Cash Flow'!B14 -> 6.471777 | C16: =-'Income Statement'!C19/' Cash Flow'!C14 -> 2.1635337 | D16: =-'Income Statement'!D19/' Cash Flow'!D14 -> 2.8261301 | E16: =-'Income Statement'!E19/' Cash Flow'!E14 -> 2.807795
A17: Debt service coverage ratio | B17: =-'Income Statement'!B16/(' Cash Flow'!B28+' Cash Flow'!B31) -> 4.3580931 | C17: =-'Income Statement'!C16/(' Cash Flow'!C28+' Cash Flow'!C31) -> 2.5104031 | D17: =-'Income Statement'!D16/(' Cash Flow'!D28+' Cash Flow'!D31) -> 1.9648722 | E17: =-'Income Statement'!E16/(' Cash Flow'!E28+' Cash Flow'!E31) -> 1.1993943
A19: Liquidity ratios
A20: Current ratio | B20: ='Balance Sheet'!B10/'Balance Sheet'!B27 -> 1.7516312 | C20: ='Balance Sheet'!C10/'Balance Sheet'!C27 -> 2.5647137 | D20: ='Balance Sheet'!D10/'Balance Sheet'!D27 -> 2.2297981 | E20: ='Balance Sheet'!E10/'Balance Sheet'!E27 -> 2.0533564
A21: Quick ratio | B21: =('Balance Sheet'!B10-'Balance Sheet'!B7-'Balance Sheet'!B9)/'Balance Sheet'!B27 -> 0.59224139 | C21: =('Balance Sheet'!C10-'Balance Sheet'!C7-'Balance Sheet'!C9)/'Balance Sheet'!C27 -> 0.88579697 | D21: =('Balance Sheet'!D10-'Balance Sheet'!D7-'Balance Sheet'!D9)/'Balance Sheet'!D27 -> 0.77992383 | E21: =('Balance Sheet'!E10-'Balance Sheet'!E7-'Balance Sheet'!E9)/'Balance Sheet'!E27 -> 0.66545654
A23: Efficiency ratios
A24: Days sales outstanding (DSO) | B24: =(B7/'Income Statement'!B4)*365 -> 24.76204 | C24: =(C7/'Income Statement'!C4)*365 -> 26.931766 | D24: =(D7/'Income Statement'!D4)*365 -> 26.679117 | E24: =(E7/'Income Statement'!E4)*365 -> 24.623957
A25: Days inventory outstanding (DIO) | B25: =-('Balance Sheet'!B7/'Income Statement'!B5)*365 -> 87.650783 | C25: =-('Balance Sheet'!C7/'Income Statement'!C5)*365 -> 75.291534 | D25: =-('Balance Sheet'!D7/'Income Statement'!D5)*365 -> 80.18802 | E25: =-('Balance Sheet'!E7/'Income Statement'!E5)*365 -> 78.441591
A26: Days payable outstanding (DPO) | B26: =-('Balance Sheet'!B24/'Income Statement'!B5)*365 -> 23.312469 | C26: =-('Balance Sheet'!C24/'Income Statement'!C5)*365 -> 27.169438 | D26: =-('Balance Sheet'!D24/'Income Statement'!D5)*365 -> 25.84163 | E26: =-('Balance Sheet'!E24/'Income Statement'!E5)*365 -> 22.339948
A27: Cash conversion cycle (CCC) | B27: =B24+B25-B26 -> 89.100354 | C27: =C24+C25-C26 -> 75.053862 | D27: =D24+D25-D26 -> 81.025507 | E27: =E24+E25-E26 -> 80.7256
